<?xml version="1.0" encoding="UTF-8"?>
<robot xmlns:xacro="http://www.ros.org/wiki/xacro">
  <xacro:macro name="wheel" params="prefix y_reflect">
    <link name="${prefix}_link">
      <visual>
        <origin xyz="0 0 0" rpy="${pi/2} 0 0"/>
        <geometry>
          <cylinder radius="${wheel_radius}" length="${wheel_width}"/>
        </geometry>
        <material name="gray"/>
      </visual>
      <collision>
        <origin xyz="0 0 0" rpy="${pi/2} 0 0"/>
        <geometry>
          <cylinder radius="${wheel_radius}" length="${wheel_width}"/>
        </geometry>
      </collision>
      <xacro:cylinder_inertia m="0.5" r="${wheel_radius}" h="${wheel_width}"/>
    </link>

    <joint name="${prefix}_joint" type="continuous">
      <parent link="base_link"/>
      <child link="${prefix}_link"/>
      <origin xyz="0 ${y_reflect * (base_width / 2 + wheel_ygap + wheel_width / 2)} ${-wheel_zoff}" rpy="0 0 0"/>
      <axis xyz="0 1 0"/>
    </joint>

    <gazebo reference="${prefix}_link">
      <material>Gazebo/Gray</material>
    </gazebo>
  </xacro:macro>

  <xacro:macro name="caster_wheel" params="prefix y_reflect">
    <link name="${prefix}_link">
      <visual>
        <geometry>
          <sphere radius="${wheel_radius}"/>
        </geometry>
        <material name="gray"/>
      </visual>
      <collision>
        <origin xyz="0 0 0" rpy="0 0 0"/>
        <geometry>
          <sphere radius="${wheel_radius}"/>
        </geometry>
      </collision>
      <xacro:sphere_inertia m="0.3" r="${wheel_radius}"/>
    </link>

    <joint name="${prefix}_joint" type="fixed">
      <parent link="base_link"/>
      <child link="${prefix}_link"/>
      <origin xyz="${caster_xoff} ${y_reflect*caster_yoff} ${-wheel_zoff}" rpy="0 0 0"/>
    </joint>

    <gazebo reference="${prefix}_link">
      <material>Gazebo/Black</material>
      <mu1 value="0.001"/>
      <mu2 value="0.001"/>
    </gazebo>
  </xacro:macro>
</robot>